Workbook

Sheet Sheet0
A1: ID | B1: CAT | C1: CODE | D1: HEADING | E1: PARENT_ID | F1: PARENT_CODE | G1: LEVEL | H1: DESC
A2: A | B2: =IF(G2>1,VLOOKUP(LEFT(C2,2),Sheet1!$A$2:$B$88,2,FALSE),C2) -> A | C2: A | D2: AGRICULTURE, FORESTRY AND FISHING | G2: 1 | H2: This section includes the exploitation of vegetal and animal natural resources, comprising the activities of growing of crops, raising and breeding of animals, harvesting of timber and other plants, and the production of animal products from a farm or natural habitats. This section also includes organic agriculture, aquaculture, the growing of genetically modified crops and the raising of genetically modified animals. This section excludes undifferentiated subsistence goods-producing activities of households, which are classified in class 98.10.
A3: 01 | B3: =IF(G3>1,VLOOKUP(LEFT(C3,2),Sheet1!$A$2:$B$88,2,FALSE),C3) -> A | C3: 01 | D3: Crop and animal production, hunting and related service activities | E3: A | F3: A | G3: 2 | H3: This division includes two basic activities, namely the production of crop products and the production of animal products. Mixed farming (group 01.5) breaks with the usual principles for identifying the main activity. It accepts that many agricultural units have a reasonably balanced production of crops and animals, and that it would be arbitrary to classify them in one category or the other. This division includes the soilless cultivation of crops, such as using hydroponic and aquaponic methods. This division also includes service activities incidental to agriculture, as well as hunting, trapping and related activities. Agricultural activities exclude any subsequent processing of the agricultural products (classified under divisions 10, 11 and 12), beyond that needed to prepare them for the primary markets. The preparation of products for the primary markets is included here. This division excludes field construction (for example, agricultural land terracing, drainage, preparing rice paddies) classified in section F and buyers and cooperative associations engaged in the marketing of farm products classified in section G. Also excluded are landscape service activities, which are classified in class 81.30.
A4: 011 | B4: =IF(G4>1,VLOOKUP(LEFT(C4,2),Sheet1!$A$2:$B$88,2,FALSE),C4) -> A | C4: 01.1 | D4: Growing of non-perennial crops | E4: 01 | F4: 01 | G4: 3 | H4: This group includes the growing of non-perennial crops, in other words, plants that do not last for more than two growing seasons. Further included is the growing of these plants for the purpose of seed production.
A5: 0111 | B5: =IF(G5>1,VLOOKUP(LEFT(C5,2),Sheet1!$A$2:$B$88,2,FALSE),C5) -> A | C5: 01.11 | D5: Growing of cereals, other than rice, leguminous crops and oil seeds | E5: 011 | F5: 01.1 | G5: 4 | H5: This class includes all forms of growing of cereals, leguminous crops and oil seeds. Further included is the growing of these plants for the purpose of seed production. The growing of these crops is often combined within agricultural units. This class includes: - growing of cereals, e.g.: • wheat • grain maize • sorghum • barley • rye • oats • millet • pseudocereals, in other words, fruits or seeds used as cereals, e.g.: • quinoa • amaranth • chia - growing of leguminous crops, e.g.: • beans • broad beans • chickpeas • cowpeas • lentils • lupines • peas • pigeon peas - growing of oil seeds, e.g.: • soya beans • groundnuts • castor beans • linseed • mustard seed • niger seed • rapeseed • safflower seed • sesame seed • sunflower seed This class excludes: - growing of rice, see 01.12 - growing of sweetcorn, see 01.13 - growing of maize, lupines or kale for fodder, see 01.19 - growing of oleaginous fruits, see 01.26
A6: 0112 | B6: =IF(G6>1,VLOOKUP(LEFT(C6,2),Sheet1!$A$2:$B$88,2,FALSE),C6) -> A | C6: 01.12 | D6: Growing of rice | E6: 011 | F6: 01.1 | G6: 4 | H6: This class includes: - growing of rice
A7: 0113 | B7: =IF(G7>1,VLOOKUP(LEFT(C7,2),Sheet1!$A$2:$B$88,2,FALSE),C7) -> A | C7: 01.13 | D7: Growing of vegetables and melons, roots and tubers | E7: 011 | F7: 01.1 | G7: 4 | H7: This class includes: - growing of leafy or stem vegetables, e.g.: • artichokes • asparagus • cabbages • cauliflower and broccoli • lettuce and chicory • spinach - growing of fruit-bearing vegetables, e.g.: • cucumbers and gherkins • eggplants (aubergines) • tomatoes • watermelons - growing of root, bulb or tuberous vegetables, e.g.: • carrots • turnips • garlic • onions (including shallots) • leeks and other alliaceous vegetables - growing of mushrooms and truffles - growing of vegetable seeds, including sugar beet seeds, excluding other beet seeds - growing of sugar beet - growing of chillies, peppers (Capsicum spp.) - growing of roots and tubers, e.g.: • potatoes • sweet potatoes • cassava • yams • swedes and mangolds This class also includes: - growing of sweetcorn This class excludes: - growing of spices and aromatic, drug and pharmaceutical crops, see 01.28 - growing of mushroom spawn, see 01.30
A8: 0114 | B8: =IF(G8>1,VLOOKUP(LEFT(C8,2),Sheet1!$A$2:$B$88,2,FALSE),C8) -> A | C8: 01.14 | D8: Growing of sugar cane | E8: 011 | F8: 01.1 | G8: 4 | H8: This class excludes: - growing of sugar beet, see 01.13
A9: 0115 | B9: =IF(G9>1,VLOOKUP(LEFT(C9,2),Sheet1!$A$2:$B$88,2,FALSE),C9) -> A | C9: 01.15 | D9: Growing of tobacco | E9: 011 | F9: 01.1 | G9: 4 | H9: This class includes: - growing of unmanufactured tobacco This class also includes: - preliminary processing of tobacco when associated with the growing of tobacco This class excludes: - preparation of tobacco leaves (e.g. sun drying) by a third party, see 01.63 - manufacture of tobacco products, see 12.00
A10: 0116 | B10: =IF(G10>1,VLOOKUP(LEFT(C10,2),Sheet1!$A$2:$B$88,2,FALSE),C10) -> A | C10: 01.16 | D10: Growing of fibre crops | E10: 011 | F10: 01.1 | G10: 4 | H10: This class includes growing of fibre crops, e.g.: - growing of cotton - growing of jute, kenaf and other textile bast fibres - growing of flax and hemp - growing of sisal and other textile fibre of the genus agave - growing of abaca, ramie and other vegetable textile fibres
A11: 0119 | B11: =IF(G11>1,VLOOKUP(LEFT(C11,2),Sheet1!$A$2:$B$88,2,FALSE),C11) -> A | C11: 01.19 | D11: Growing of other non-perennial crops | E11: 011 | F11: 01.1 | G11: 4 | H11: This class includes the growing of all other non-perennial crops, e.g.: - growing of clover, alfalfa, sainfoin, maize, lupines, other grasses, fodder kale and similar forage crops - growing of beet seeds and seeds of forage plants - growing of flowers - cutting of flowers and flower buds - growing of flower seeds This class also includes: - growing of perennial flowers and other ornamental plants This class excludes: - growing of sugar beet seeds, see 01.13 - growing of non-perennial spices and aromatic, drug and pharmaceutical crops, see 01.28
A12: 012 | B12: =IF(G12>1,VLOOKUP(LEFT(C12,2),Sheet1!$A$2:$B$88,2,FALSE),C12) -> A | C12: 01.2 | D12: Growing of perennial crops | E12: 01 | F12: 01 | G12: 3 | H12: This group includes the growing of perennial crops, in other words, plants that last for more than two growing seasons, either dying back after each season or growing continuously. Further included is the growing of these plants for the purpose of seed production. This group excludes: - growing of perennial flowers and other ornamental plants, see 01.19
A13: 0121 | B13: =IF(G13>1,VLOOKUP(LEFT(C13,2),Sheet1!$A$2:$B$88,2,FALSE),C13) -> A | C13: 01.21 | D13: Growing of grapes | E13: 012 | F13: 01.2 | G13: 4 | H13: This class includes: - growing of grapes for consumption or for further production of wine, juice, vinegar and dried fruit (e.g. raisins, zante currants or sultanas) This class excludes: - manufacture of juice, see 10.32 - manufacture of wine, see 11.02
A14: 0122 | B14: =IF(G14>1,VLOOKUP(LEFT(C14,2),Sheet1!$A$2:$B$88,2,FALSE),C14) -> A | C14: 01.22 | D14: Growing of tropical and subtropical fruits | E14: 012 | F14: 01.2 | G14: 4 | H14: This class includes: - growing of tropical and subtropical fruits, e.g.: • avocados • bananas and plantains • dates • figs • mangoes • papayas • pineapples • rambutans • lychees
... A21: 0129 | B21: =IF(G21>1,VLOOKUP(LEFT(C21,2),Sheet1!$A$2:$B$88,2,FALSE),C21) -> A | C21: 01.29 | D21: Growing of other perennial crops | E21: 012 | F21: 01.2 | G21: 4 | H21: This class includes: - growing of rubber trees for harvesting of latex - growing of Christmas trees - growing of trees for extraction of sap - growing of vegetable materials of a kind used primarily for plaiting This class excludes: - growing of flowers, cutting of flower buds and growing of flower seeds, see 01.19 - gathering of tree sap or rubber-like gums in the wild, see 02.30
A22: 013 | B22: =IF(G22>1,VLOOKUP(LEFT(C22,2),Sheet1!$A$2:$B$88,2,FALSE),C22) -> A | C22: 01.3 | D22: Plant propagation | E22: 01 | F22: 01 | G22: 3
A23: 0130 | B23: =IF(G23>1,VLOOKUP(LEFT(C23,2),Sheet1!$A$2:$B$88,2,FALSE),C23) -> A | C23: 01.30 | D23: Plant propagation | E23: 013 | F23: 01.3 | G23: 4 | H23: This class includes the production of all vegetative planting materials, including cuttings, suckers and seedlings either for direct plant propagation or to create plant grafting stock into which a selected scion is grafted for eventual planting to produce crops. This class includes: - growing of plants for planting - growing of plants for ornamental purposes, including turf for transplanting - growing of live plants for bulbs, tubers and roots, cuttings and slips, and mushroom spawn - operation of tree nurseries, except forest tree nurseries This class excludes: - growing of plants for the purpose of seed production, see 01.1, 01.2 - operation of forest tree nurseries, see 02.10
A24: 014 | B24: =IF(G24>1,VLOOKUP(LEFT(C24,2),Sheet1!$A$2:$B$88,2,FALSE),C24) -> A | C24: 01.4 | D24: Animal production | E24: 01 | F24: 01 | G24: 3 | H24: This group includes: - farming (husbandry, raising) and breeding of all animals, except aquatic animals This group excludes: - farm animal boarding and care, see 01.62 - production of hides and skins from slaughterhouses, see 10.11
A25: 0141 | B25: =IF(G25>1,VLOOKUP(LEFT(C25,2),Sheet1!$A$2:$B$88,2,FALSE),C25) -> A | C25: 01.41 | D25: Raising of dairy cattle | E25: 014 | F25: 01.4 | G25: 4 | H25: This class includes: - raising and breeding of dairy cattle and/or buffaloes - production of raw milk from cows or buffaloes - production of bovine semen of dairy breeds This class excludes: - processing of milk, see 10.51
A26: 0142 | B26: =IF(G26>1,VLOOKUP(LEFT(C26,2),Sheet1!$A$2:$B$88,2,FALSE),C26) -> A | C26: 01.42 | D26: Raising of other cattle and buffaloes | E26: 014 | F26: 01.4 | G26: 4 | H26: This class includes: - raising and breeding of cattle and buffaloes for meat - production of bovine semen of meat breeds This class also includes: - raising and breeding of draft cattle or buffaloes - raising and breeding of fighting bulls
A27: 0143 | B27: =IF(G27>1,VLOOKUP(LEFT(C27,2),Sheet1!$A$2:$B$88,2,FALSE),C27) -> A | C27: 01.43 | D27: Raising of horses and other equines | E27: 014 | F27: 01.4 | G27: 4 | H27: This class includes: - raising and breeding of horses, asses, mules or hinnies, regardless of the purpose This class excludes: - operation of racing and riding stables (if they do not have breeding activities), see 93.19
A28: 0144 | B28: =IF(G28>1,VLOOKUP(LEFT(C28,2),Sheet1!$A$2:$B$88,2,FALSE),C28) -> A | C28: 01.44 | D28: Raising of camels and camelids | E28: 014 | F28: 01.4 | G28: 4 | H28: This class includes: - raising and breeding of camels (dromedary) and camelids
A29: 0145 | B29: =IF(G29>1,VLOOKUP(LEFT(C29,2),Sheet1!$A$2:$B$88,2,FALSE),C29) -> A | C29: 01.45 | D29: Raising of sheep and goats | E29: 014 | F29: 01.4 | G29: 4 | H29: This class includes: - raising and breeding of sheep and goats - production of raw sheep or goat milk - production of raw wool This class excludes: - sheep shearing on a fee or contract basis, see 01.62 - production of pulled wool, see 10.11 - processing of milk, see 10.51
A30: 0146 | B30: =IF(G30>1,VLOOKUP(LEFT(C30,2),Sheet1!$A$2:$B$88,2,FALSE),C30) -> A | C30: 01.46 | D30: Raising of swine and pigs | E30: 014 | F30: 01.4 | G30: 4 | H30: This class includes: - raising and breeding of swine and pigs
A31: 0147 | B31: =IF(G31>1,VLOOKUP(LEFT(C31,2),Sheet1!$A$2:$B$88,2,FALSE),C31) -> A | C31: 01.47 | D31: Raising of poultry | E31: 014 | F31: 01.4 | G31: 4 | H31: This class includes: - raising and breeding of poultry, e.g.: • chickens, turkeys, ducks, geese, quails, ostriches or guineafowls - production of eggs from poultry - operation of poultry hatcheries - automated egg hatching for poultry This class excludes: - production of feathers or down, see 10.12
A32: 0148 | B32: =IF(G32>1,VLOOKUP(LEFT(C32,2),Sheet1!$A$2:$B$88,2,FALSE),C32) -> A | C32: 01.48 | D32: Raising of other animals | E32: 014 | F32: 01.4 | G32: 4 | H32: This class includes: - raising and breeding of semi-domesticated or other live animals, e.g.: • birds (except poultry and ostriches) • insects • rabbits and other fur animals • reindeer - production of bird skins from ranching operations or skins from farming reptiles (e.g. snakes and turtles) - raising and breeding of reptiles, except crocodiles - operation of land worm farms, land mollusc farms, land snail farms, etc. - raising of silkworms, production of silkworm cocoons - beekeeping; production of bees’ byproducts (e.g. honey, beeswax, propolis, bee venom or honeycomb); bee propagation for sale - raising and breeding of pets (except fish), e.g.: • cats and dogs • birds (e.g. parakeets) • hamsters This class excludes: - production of hides and skins originating from hunting and trapping, see 01.70 - raising of live ornamental fish, see 03.2 - operation of frog farms, crocodile farms, marine worm farms, see 03.21, 03.22 - operation of fish farms, see 03.21, 03.22 - boarding and training of pets, see 96.99 - operation of shelters for abandoned pets, see 96.99
A33: 015 | B33: =IF(G33>1,VLOOKUP(LEFT(C33,2),Sheet1!$A$2:$B$88,2,FALSE),C33) -> A | C33: 01.5 | D33: Mixed farming | E33: 01 | F33: 01 | G33: 3
A34: 0150 | B34: =IF(G34>1,VLOOKUP(LEFT(C34,2),Sheet1!$A$2:$B$88,2,FALSE),C34) -> A | C34: 01.50 | D34: Mixed farming | E34: 015 | F34: 01.5 | G34: 4 | H34: This class includes: - the combined production of crops and animals without a specialised production of crops or animals This class excludes: - mixed crop farming, see 01.1, 01.2 - mixed animal farming, see 01.4
A35: 016 | B35: =IF(G35>1,VLOOKUP(LEFT(C35,2),Sheet1!$A$2:$B$88,2,FALSE),C35) -> A | C35: 01.6 | D35: Support activities to agriculture and post-harvest crop activities | E35: 01 | F35: 01 | G35: 3 | H35: This group includes activities incidental to agricultural production and activities similar to agriculture not undertaken for production purposes (in the sense of harvesting agricultural products), usually done on a fee or contract basis. Also included are post-harvest crop activities, aimed at preparing agricultural products for the primary market.
A36: 0161 | B36: =IF(G36>1,VLOOKUP(LEFT(C36,2),Sheet1!$A$2:$B$88,2,FALSE),C36) -> A | C36: 01.61 | D36: Support activities for crop production | E36: 016 | F36: 01.6 | G36: 4 | H36: This class includes: - crop production activities on a fee or contract basis: • preparation of fields • establishing a crop • treatment of crops • crop spraying, including by air • trimming of fruit trees and vines • transplanting of rice; thinning of beets • harvesting • pest control (including of rabbits) in connection with agriculture - operation of agricultural irrigation equipment This class also includes: - provision of agricultural machinery with operators and crew - maintenance of own or leased land, keeping it in good condition without agricultural production This class excludes: - post-harvest crop activities, see 01.63 - drainage of agricultural land, see 43.12 - landscape architecture, see 71.11 - activities of agronomists and agricultural economists, see 74.99 - landscape gardening; planting, see 81.30 - organisation of agricultural shows and fairs, see 82.30
A37: 0162 | B37: =IF(G37>1,VLOOKUP(LEFT(C37,2),Sheet1!$A$2:$B$88,2,FALSE),C37) -> A | C37: 01.62 | D37: Support activities for animal production | E37: 016 | F37: 01.6 | G37: 4 | H37: This class includes: - animal production activities on a fee or contract basis: • activities to promote the propagation, growth and output of animals • herd testing services, droving services, agistment services, poultry caponising, coop cleaning, etc. • activities related to artificial insemination • stud services • sheep shearing • farm animal boarding and care This class also includes: - activities of farriers This class excludes: - provision of space for animal boarding only, see 68.20 - agricultural research activities, see 72.10 - veterinary activities, see 75.00 - vaccination of animals, see 75.00 - rental of animals (e.g. herds or racehorses), see 77.39 - pet boarding, see 96.99
A38: 0163 | B38: =IF(G38>1,VLOOKUP(LEFT(C38,2),Sheet1!$A$2:$B$88,2,FALSE),C38) -> A | C38: 01.63 | D38: Post-harvest crop activities and seed processing for propagation | E38: 016 | F38: 01.6 | G38: 4 | H38: This class includes post-harvest crop activities on a fee or contract basis: - preparation of crops for primary markets (e.g. cleaning, trimming, grading or disinfecting) - cotton ginning - preparation of tobacco leaves (e.g. sun drying) - preparation of cocoa beans (e.g. peeling) - waxing of fruit - drying of fruit, vegetables, herbs, spices, medicinal herbs and tobacco - sorting, cleaning and cutting of medicinal herbs - grain drying - post-harvest activities aimed at improving the propagation quality of seed (e.g. by the removal of non-seed materials, or damaged or immature seeds, or by reducing the seed moisture to a safe level for storage) - retting of plants bearing vegetable textile fibres (such as jute, flax or coir), not associated with the growing of vegetable textile fibres - artificial ripening of fruits as a service (e.g. banana ripening) This class also includes: - drying, cleaning, grading and treating of seeds until they are marketed - treatment of genetically modified seeds This class excludes: - preparation of agricultural products by the producer, see the corresponding classes in groups 01.1, 01.2, 01.3 - growing of seeds, see 01.1, 01.2 - processing of seeds to obtain oil, see 10.41 - stemming and redrying of tobacco, see 12.00 - marketing activities of commission merchants and cooperative associations, see division 46 - wholesale of agricultural raw materials, see 46.2 - research to develop or modify new forms of seeds, see 72.10
A39: 017 | B39: =IF(G39>1,VLOOKUP(LEFT(C39,2),Sheet1!$A$2:$B$88,2,FALSE),C39) -> A | C39: 01.7 | D39: Hunting, trapping and related service activities | E39: 01 | F39: 01 | G39: 3
A40: 0170 | B40: =IF(G40>1,VLOOKUP(LEFT(C40,2),Sheet1!$A$2:$B$88,2,FALSE),C40) -> A | C40: 01.70 | D40: Hunting, trapping and related service activities | E40: 017 | F40: 01.7 | G40: 4 | H40: This class includes: - hunting and trapping on a commercial basis - taking of wild animals (dead or alive) for i) food, fur or skin and ii) use in research, in zoos or as pets - production of fur skins and reptile or bird skins from hunting or trapping activities - catching of frogs and collecting of snails in the wild This class also includes: - land-based catching of sea mammals (e.g. walruses or seals) - hunting of foxes, minks and wolves to protect livestock - hunting for animal population control This class excludes: - raising of game animals on ranching operations, see 01.4 - production of bird skins from ranching operations or skins from farming reptiles (e.g. snakes and turtles), see 01.48 - pest control (including rabbits) in connection with agriculture, see 01.61 - whaling, see 03.11 - production of hides and skins originating from slaughterhouses, see 10.11 - hunting for sport or recreation and related service activities, see 93.19 - service activities to promote hunting and trapping, see 94.99
A41: 02 | B41: =IF(G41>1,VLOOKUP(LEFT(C41,2),Sheet1!$A$2:$B$88,2,FALSE),C41) -> A | C41: 02 | D41: Forestry and logging | E41: A | F41: A | G41: 2 | H41: This division includes silviculture and the production of roundwood as well as the extraction and gathering of wild-growing non-wood forest products. Besides the production of timber, forestry activities result in products that undergo little processing, for example, firewood, charcoal or roundwood used in an unprocessed form (such as pit-props or pulpwood). These activities can be carried out in natural, semi-natural or planted forests. Excluded is further processing of wood beginning with sawmilling and planing of wood, see division 16.
A42: 021 | B42: =IF(G42>1,VLOOKUP(LEFT(C42,2),Sheet1!$A$2:$B$88,2,FALSE),C42) -> A | C42: 02.1 | D42: Silviculture and other forestry activities | E42: 02 | F42: 02 | G42: 3
A43: 0210 | B43: =IF(G43>1,VLOOKUP(LEFT(C43,2),Sheet1!$A$2:$B$88,2,FALSE),C43) -> A | C43: 02.10 | D43: Silviculture and other forestry activities | E43: 021 | F43: 02.1 | G43: 4 | H43: This class includes: - growing of standing timber: planting, replanting, transplanting, thinning and conserving of forests, and timber tracts - growing of coppice, pulpwood and firewood - operation of forest tree nurseries - growing of poplar and willow These activities can be carried out in natural, semi-natural or planted forests. This class excludes: - growing of Christmas trees, see 01.29 - operation of tree nurseries, except for forest trees, see 01.30 - gathering of mushrooms and other wild growing non-wood forest products, see 02.30 - production of wood chips and particles, not associated with forestry activities, see 16.11 - production of wood fire logs not associated with forestry activities, see 16.26 - activities relating to amenity tree care and arboriculture, see 81.30 - conservation and maintenance services of national parks, nature parks and reserves, see 91.42
A44: 022 | B44: =IF(G44>1,VLOOKUP(LEFT(C44,2),Sheet1!$A$2:$B$88,2,FALSE),C44) -> A | C44: 02.2 | D44: Logging | E44: 02 | F44: 02 | G44: 3
A45: 0220 | B45: =IF(G45>1,VLOOKUP(LEFT(C45,2),Sheet1!$A$2:$B$88,2,FALSE),C45) -> A | C45: 02.20 | D45: Logging | E45: 022 | F45: 02.2 | G45: 4 | H45: This class includes: - production of roundwood for forest-based manufacturing industries - production of roundwood used in an unprocessed form (e.g. pit-props, fence posts, utility poles) This class also includes: - gathering and production of forest harvesting residues (e.g. brushwood, stumps, wood chips from logging, other forest waste for energy) - production of charcoal in the forest (using traditional methods) This class excludes: - growing of Christmas trees, see 01.29 - growing of standing timber: planting, replanting, transplanting, thinning and conserving of forests, and timber tracts, see 02.10 - gathering of wild growing non-wood forest products, see 02.30 - production of wood chips and particles, not associated with forestry activities, see 16.11 - production of charcoal through distillation of wood, see 20.14
A46: 023 | B46: =IF(G46>1,VLOOKUP(LEFT(C46,2),Sheet1!$A$2:$B$88,2,FALSE),C46) -> A | C46: 02.3 | D46: Gathering of wild growing non-wood products | E46: 02 | F46: 02 | G46: 3
...

Sheet Sheet1
A1: CODE | B1: PARENT_CODE | C1: LEVEL
A2: 01 | B2: A | C2: 2
A3: 02 | B3: A | C3: 2
A4: 03 | B4: A | C4: 2
A5: 05 | B5: B | C5: 2
A6: 06 | B6: B | C6: 2
A7: 07 | B7: B | C7: 2
A8: 08 | B8: B | C8: 2
A9: 09 | B9: B | C9: 2
A10: 10 | B10: C | C10: 2
A11: 11 | B11: C | C11: 2
A12: 12 | B12: C | C12: 2
... A88: 99 | B88: V | C88: 2
